Workbook

Sheet ASSUMPTIONS
A1: VITAFLOW HEALTH — MODEL ASSUMPTIONS
A2: All inputs are entered here. Do not hardcode values in other tabs
A4: BUSINESS SETTINGS
A5: Company Name | B5: VitaFlow Health
A6: Model Start Date | B6: 45658
A7: Forecast Horizon (Months) | B7: 6
A8: Base Currency | B8: USD
A9: VAT / Tax Rate | B9: 0 | C9: percent
A11: SALES ASSUMPTIONS
A12: Monthly Growth Rate (Base) | B12: 0.05 | C12: percent
A13: Monthly Growth Rate (Best) | B13: 0.1 | C13: percent
A14: Monthly Growth Rate (Conservative) | B14: 0.02 | C14: percent
A15: Active Scenario | B15: Base
A16: Seasonality Boost — Q4 (Oct–Dec) | B16: 0.2 | C16: percent
A17: Seasonality Boost — Q1 (Jan–Mar) | B17: -0.1 | C17: percent
A19: INVENTORY ASSUMPTIONS
A20: Reorder Point (Days of Stock) | B20: =B21+B22 -> 54 | C20: days
A21: Average Supplier Lead Time | B21: 40 | C21: days
A22: Safety Stock Buffer | B22: 14 | C22: days
A23: Stockout Alert Threshold | B23: 10 | C23: days
A25: CASH FLOW ASSUMPTIONS
A26: Shopify Payout Delay (Days) | B26: 3 | C26: days after sale
A27: Supplier Payment Terms | B27: 30 | C27: days net
A28: Opening Cash Balance | B28: 50000 | C28: Format as currency
A29: Monthly Operating Expenses | B29: 28000 | C29: Format as currency
A30: Shipping Cost per Order | B30: 4.5 | C30: Format as currency
A31: Shopify Transaction Fee Rate | B31: 0.029 | C31: Percent
A32: SKU REFERENCE TABLE
A33: SKU Code | B33: Product Name | C33: Unit Price (USD)
A34: VF-001 | B34: Omega-3 Fish Oil 90 caps | C34: 24.99
A35: VF-002 | B35: Magnesium Complex 60 caps | C35: 19.99
A36: VF-003 | B36: Vitamin D3 120 caps | C36: 17.99
A37: VF-004 | B37: Collagen Peptides 500g | C37: 34.99
A38: VF-005 | B38: Probiotic Blend 30 caps | C38: 29.99

Sheet SALES DATA
A1: VITAFLOW HEALTH — HISTORICAL SALES DATA (JAN–DEC 2024)
A2: Units sold per SKU per month. Source: Shopify export
A4: SKU Code | B4: Product Name | C4: Jan | D4: Feb | E4: Mar | F4: Apr | G4: May | H4: Jun | I4: Jul | J4: Aug | K4: Sep | L4: Oct | M4: Nov | N4: Dec | O4: TOTAL UNITS
A5: VF-001 | B5: Omega-3 Fish Oil 90 caps | C5: 320 | D5: 295 | E5: 310 | F5: 330 | G5: 350 | H5: 360 | I5: 370 | J5: 365 | K5: 380 | L5: 430 | M5: 520 | N5: 610 | O5: =SUM(C5:N5) -> 4640
A6: VF-002 | B6: Magnesium Complex 60 caps | C6: 210 | D6: 195 | E6: 205 | F6: 220 | G6: 240 | H6: 245 | I6: 255 | J6: 260 | K6: 270 | L6: 310 | M6: 390 | N6: 450 | O6: =SUM(C6:N6) -> 3250
A7: VF-003 | B7: Vitamin D3 120 caps | C7: 180 | D7: 165 | E7: 170 | F7: 175 | G7: 185 | H7: 190 | I7: 200 | J7: 205 | K7: 215 | L7: 260 | M7: 330 | N7: 400 | O7: =SUM(C7:N7) -> 2675
A8: VF-004 | B8: Collagen Peptides 500g | C8: 140 | D8: 128 | E8: 135 | F8: 150 | G8: 165 | H8: 172 | I8: 180 | J8: 185 | K8: 192 | L8: 220 | M8: 275 | N8: 320 | O8: =SUM(C8:N8) -> 2262
A9: VF-005 | B9: Probiotic Blend 30 caps | C9: 260 | D9: 240 | E9: 250 | F9: 265 | G9: 280 | H9: 290 | I9: 300 | J9: 305 | K9: 315 | L9: 360 | M9: 440 | N9: 510 | O9: =SUM(C9:N9) -> 3815
A10: MONTHLY TOTAL | C10: =SUM(C5:C9) -> 1110 | D10: =SUM(D5:D9) -> 1023 | E10: =SUM(E5:E9) -> 1070 | F10: =SUM(F5:F9) -> 1140 | G10: =SUM(G5:G9) -> 1220 | H10: =SUM(H5:H9) -> 1257 | I10: =SUM(I5:I9) -> 1305 | J10: =SUM(J5:J9) -> 1320 | ... O10: =SUM(O5:O9) -> 16642
A12: REVENUE BY SKU (USD)
A13: SKU Code | B13: Product Name | C13: Jan | D13: Feb | E13: Mar | F13: Apr | G13: May | H13: Jun | I13: Jul | J13: Aug | K13: Sep | L13: Oct | M13: Nov | N13: Dec | O13: TOTAL UNITS
A14: =A5 -> VF-001 | B14: =B5 -> Omega-3 Fish Oil 90 caps | C14: =C5*VLOOKUP($A14,ASSUMPTIONS!$A$34:$C$38,3,0) -> 7996.8 | D14: =D5*VLOOKUP($A14,ASSUMPTIONS!$A$34:$C$38,3,0) -> 7372.05 | E14: =E5*VLOOKUP($A14,ASSUMPTIONS!$A$34:$C$38,3,0) -> 7746.9 | F14: =F5*VLOOKUP($A14,ASSUMPTIONS!$A$34:$C$38,3,0) -> 8246.7 | G14: =G5*VLOOKUP($A14,ASSUMPTIONS!$A$34:$C$38,3,0) -> 8746.5 | H14: =H5*VLOOKUP($A14,ASSUMPTIONS!$A$34:$C$38,3,0) -> 8996.4 | I14: =I5*VLOOKUP($A14,ASSUMPTIONS!$A$34:$C$38,3,0) -> 9246.3 | J14: =J5*VLOOKUP($A14,ASSUMPTIONS!$A$34:$C$38,3,0) -> 9121.35 | ... N14: =N5*VLOOKUP($A14,ASSUMPTIONS!$A$34:$C$38,3,0) -> 15243.9 | O14: =SUM(C14:N14) -> 115953.6
A15: =A6 -> VF-002 | B15: =B6 -> Magnesium Complex 60 caps | C15: =C6*VLOOKUP($A15,ASSUMPTIONS!$A$34:$C$38,3,0) -> 4197.9 | D15: =D6*VLOOKUP($A15,ASSUMPTIONS!$A$34:$C$38,3,0) -> 3898.05 | E15: =E6*VLOOKUP($A15,ASSUMPTIONS!$A$34:$C$38,3,0) -> 4097.95 | F15: =F6*VLOOKUP($A15,ASSUMPTIONS!$A$34:$C$38,3,0) -> 4397.8 | G15: =G6*VLOOKUP($A15,ASSUMPTIONS!$A$34:$C$38,3,0) -> 4797.6 | H15: =H6*VLOOKUP($A15,ASSUMPTIONS!$A$34:$C$38,3,0) -> 4897.55 | I15: =I6*VLOOKUP($A15,ASSUMPTIONS!$A$34:$C$38,3,0) -> 5097.45 | J15: =J6*VLOOKUP($A15,ASSUMPTIONS!$A$34:$C$38,3,0) -> 5197.4 | ... N15: =N6*VLOOKUP($A15,ASSUMPTIONS!$A$34:$C$38,3,0) -> 8995.5 | O15: =SUM(C15:N15) -> 64967.5
A16: =A7 -> VF-003 | B16: =B7 -> Vitamin D3 120 caps | C16: =C7*VLOOKUP($A16,ASSUMPTIONS!$A$34:$C$38,3,0) -> 3238.2 | D16: =D7*VLOOKUP($A16,ASSUMPTIONS!$A$34:$C$38,3,0) -> 2968.35 | E16: =E7*VLOOKUP($A16,ASSUMPTIONS!$A$34:$C$38,3,0) -> 3058.3 | F16: =F7*VLOOKUP($A16,ASSUMPTIONS!$A$34:$C$38,3,0) -> 3148.25 | G16: =G7*VLOOKUP($A16,ASSUMPTIONS!$A$34:$C$38,3,0) -> 3328.15 | H16: =H7*VLOOKUP($A16,ASSUMPTIONS!$A$34:$C$38,3,0) -> 3418.1 | I16: =I7*VLOOKUP($A16,ASSUMPTIONS!$A$34:$C$38,3,0) -> 3598 | J16: =J7*VLOOKUP($A16,ASSUMPTIONS!$A$34:$C$38,3,0) -> 3687.95 | ... N16: =N7*VLOOKUP($A16,ASSUMPTIONS!$A$34:$C$38,3,0) -> 7196 | O16: =SUM(C16:N16) -> 48123.25
A17: =A8 -> VF-004 | B17: =B8 -> Collagen Peptides 500g | C17: =C8*VLOOKUP($A17,ASSUMPTIONS!$A$34:$C$38,3,0) -> 4898.6 | D17: =D8*VLOOKUP($A17,ASSUMPTIONS!$A$34:$C$38,3,0) -> 4478.72 | E17: =E8*VLOOKUP($A17,ASSUMPTIONS!$A$34:$C$38,3,0) -> 4723.65 | F17: =F8*VLOOKUP($A17,ASSUMPTIONS!$A$34:$C$38,3,0) -> 5248.5 | G17: =G8*VLOOKUP($A17,ASSUMPTIONS!$A$34:$C$38,3,0) -> 5773.35 | H17: =H8*VLOOKUP($A17,ASSUMPTIONS!$A$34:$C$38,3,0) -> 6018.28 | I17: =I8*VLOOKUP($A17,ASSUMPTIONS!$A$34:$C$38,3,0) -> 6298.2 | J17: =J8*VLOOKUP($A17,ASSUMPTIONS!$A$34:$C$38,3,0) -> 6473.15 | ... N17: =N8*VLOOKUP($A17,ASSUMPTIONS!$A$34:$C$38,3,0) -> 11196.8 | O17: =SUM(C17:N17) -> 79147.38
A18: =A9 -> VF-005 | B18: =B9 -> Probiotic Blend 30 caps | C18: =C9*VLOOKUP($A18,ASSUMPTIONS!$A$34:$C$38,3,0) -> 7797.4 | D18: =D9*VLOOKUP($A18,ASSUMPTIONS!$A$34:$C$38,3,0) -> 7197.6 | E18: =E9*VLOOKUP($A18,ASSUMPTIONS!$A$34:$C$38,3,0) -> 7497.5 | F18: =F9*VLOOKUP($A18,ASSUMPTIONS!$A$34:$C$38,3,0) -> 7947.35 | G18: =G9*VLOOKUP($A18,ASSUMPTIONS!$A$34:$C$38,3,0) -> 8397.2 | H18: =H9*VLOOKUP($A18,ASSUMPTIONS!$A$34:$C$38,3,0) -> 8697.1 | I18: =I9*VLOOKUP($A18,ASSUMPTIONS!$A$34:$C$38,3,0) -> 8997 | J18: =J9*VLOOKUP($A18,ASSUMPTIONS!$A$34:$C$38,3,0) -> 9146.95 | ... N18: =N9*VLOOKUP($A18,ASSUMPTIONS!$A$34:$C$38,3,0) -> 15294.9 | O18: =SUM(C18:N18) -> 114411.85
A19: TOTAL TOTAL | C19: =SUM(C14:C18) -> 28128.9 | D19: =SUM(D14:D18) -> 25914.77 | E19: =SUM(E14:E18) -> 27124.3 | F19: =SUM(F14:F18) -> 28988.6 | G19: =SUM(G14:G18) -> 31042.8 | H19: =SUM(H14:H18) -> 32027.43 | I19: =SUM(I14:I18) -> 33236.95 | J19: =SUM(J14:J18) -> 33626.8 | ... O19: =SUM(O14:O18) -> 422603.58
A21: AVERAGE MONTHLY UNITS (for Forecasting)
A22: sku Code | B22: Product Name | C22: Avg Monthly Units
A23: =A5 -> VF-001 | B23: =B5 -> Omega-3 Fish Oil 90 caps | C23: =AVERAGE($C5:$N5) -> 386.66667
A24: =A6 -> VF-002 | B24: =B6 -> Magnesium Complex 60 caps | C24: =AVERAGE($C6:$N6) -> 270.83333
A25: =A7 -> VF-003 | B25: =B7 -> Vitamin D3 120 caps | C25: =AVERAGE($C7:$N7) -> 222.91667
A26: =A8 -> VF-004 | B26: =B8 -> Collagen Peptides 500g | C26: =AVERAGE($C8:$N8) -> 188.5
A27: =A9 -> VF-005 | B27: =B9 -> Probiotic Blend 30 caps | C27: =AVERAGE($C9:$N9) -> 317.91667

Sheet INVENTORY
A1: VITAFLOW HEALTH — INVENTORY TRACKER & PO SCHEDULE
A2: Current stock levels, open purchase orders, and reorder alerts as at 01/01/2025
A4: CURRENT INVENTORY POSITIONS
A5: SKU Code | B5: Product Name | C5: Unit Cost (USD) | D5: Units in Stock | E5: Avg Daily Sales | F5: Days of Stock Left | G5: Reorder Point (Units) | H5: Safety Stock (Units) | I5: Stock Status
A6: =ASSUMPTIONS!A34 -> VF-001 | B6: {=ASSUMPTIONS!B34:B38} -> Omega-3 Fish Oil 90 caps | C6: 8.5 | D6: 850 | E6: {='SALES DATA'!O5:O9/365} -> 12.712329 | F6: =IFERROR($D6/$E6,0) -> 66.864224 | G6: =(ASSUMPTIONS!$B$20)*INVENTORY!$E6 -> 686.46575 | H6: =ASSUMPTIONS!$B$22*INVENTORY!$E6 -> 177.9726 | I6: =IF($F6<=ASSUMPTIONS!$B$23,"🔴 CRITICAL", IF($F6<=ASSUMPTIONS!$B$20,"🟡 REORDER NOW","🟢 OK")) -> 🟢 OK
A7: =ASSUMPTIONS!A35 -> VF-002 | B7: Magnesium Complex 60 caps | C7: 6.8 | D7: 520 | E7: 8.9041096 | F7: =IFERROR($D7/$E7,0) -> 58.4 | G7: =(ASSUMPTIONS!$B$20)*INVENTORY!$E7 -> 480.82192 | H7: =ASSUMPTIONS!$B$22*INVENTORY!$E7 -> 124.65753 | I7: =IF($F7<=ASSUMPTIONS!$B$23,"🔴 CRITICAL", IF($F7<=ASSUMPTIONS!$B$20,"🟡 REORDER NOW","🟢 OK")) -> 🟢 OK
A8: =ASSUMPTIONS!A36 -> VF-003 | B8: Vitamin D3 120 caps | C8: 5.9 | D8: 430 | E8: 7.3287671 | F8: =IFERROR($D8/$E8,0) -> 58.672897 | G8: =(ASSUMPTIONS!$B$20)*INVENTORY!$E8 -> 395.75342 | H8: =ASSUMPTIONS!$B$22*INVENTORY!$E8 -> 102.60274 | I8: =IF($F8<=ASSUMPTIONS!$B$23,"🔴 CRITICAL", IF($F8<=ASSUMPTIONS!$B$20,"🟡 REORDER NOW","🟢 OK")) -> 🟢 OK
A9: =ASSUMPTIONS!A37 -> VF-004 | B9: Collagen Peptides 500g | C9: 12.4 | D9: 310 | E9: 6.1972603 | F9: =IFERROR($D9/$E9,0) -> 50.022104 | G9: =(ASSUMPTIONS!$B$20)*INVENTORY!$E9 -> 334.65205 | H9: =ASSUMPTIONS!$B$22*INVENTORY!$E9 -> 86.761644 | I9: =IF($F9<=ASSUMPTIONS!$B$23,"🔴 CRITICAL", IF($F9<=ASSUMPTIONS!$B$20,"🟡 REORDER NOW","🟢 OK")) -> 🟡 REORDER NOW
A10: =ASSUMPTIONS!A38 -> VF-005 | B10: Probiotic Blend 30 caps | C10: 9.2 | D10: 680 | E10: 10.452055 | F10: =IFERROR($D10/$E10,0) -> 65.058978 | G10: =(ASSUMPTIONS!$B$20)*INVENTORY!$E10 -> 564.41096 | H10: =ASSUMPTIONS!$B$22*INVENTORY!$E10 -> 146.32877 | I10: =IF($F10<=ASSUMPTIONS!$B$23,"🔴 CRITICAL", IF($F10<=ASSUMPTIONS!$B$20,"🟡 REORDER NOW","🟢 OK")) -> 🟢 OK
A12: OPEN PURCHASE ORDERS (POs)
A13: PO Number | B13: SKU Code | C13: Product Name | D13: Units Ordered | E13: Unit Cost (USD) | F13: Total PO Value | G13: Order Date | H13: Expected Landing Date | I13: Days Until Landing | J13: Payment Due Date | K13: Payment Status | L13: Notes
A14: PO-2025-001 | B14: VF-001 | C14: Omega-3 Fish Oil 90 caps | D14: 1200 | E14: 8.5 | F14: =D14*E14 -> 10200 | G14: 45641 | H14: 45677 | I14: =H14-G14 -> 36 | J14: 45671 | K14: Paid | L14: Seasonal stock
A15: PO-2025-002 | B15: VF-003 | C15: Vitamin D3 120 caps | D15: 900 | E15: 5.9 | F15: =D15*E15 -> 5310 | G15: 45646 | H15: 45682 | I15: =H15-G15 -> 36 | J15: 45676 | K15: Paid | L15: Low stock top-up
A16: PO-2025-003 | B16: VF-002 | C16: Magnesium Complex 60 caps | D16: 800 | E16: 6.8 | F16: =D16*E16 -> 5440 | G16: 45658 | H16: 45698 | I16: =H16-G16 -> 40 | J16: 45688 | K16: Pending | L16: Reorder trigered
A17: PO-2025-004 | B17: VF-005 | C17: Probiotic Blend 30 caps | D17: 1000 | E17: 9.2 | F17: =D17*E17 -> 9200 | G17: 45662 | H17: 45703 | I17: =H17-G17 -> 41 | J17: 45692 | K17: Pending | L17: Monthly reorder
A18: PO-2025-005 | B18: VF-004 | C18: Collagen Peptides 500g | D18: 600 | E18: 12.4 | F18: =D18*E18 -> 7440 | G18: 45667 | H18: 45708 | I18: =H18-G18 -> 41 | J18: 45697 | K18: Pending | L18: Growth stock
A19: PO-2025-006 | B19: VF-001 | C19: Omega-3 Fish Oil 90 caps | D19: 1000 | E19: 8.5 | F19: =D19*E19 -> 8500 | G19: 45672 | H19: 45717 | I19: =H19-G19 -> 45 | J19: 45702 | K19: Pending | L19: Q1 forecast
A20: PO-2025-007 | B20: VF-003 | C20: Vitamin D3 120 caps | D20: 700 | E20: 5.9 | F20: =D20*E20 -> 4130 | G20: 45677 | H20: 45726 | I20: =H20-G20 -> 49 | J20: 45707 | K20: Pending | L20: Q1 forecast
A21: TOTAL OPEN PO VALUE | F21: =SUM(F14:F20) -> 50220
A23: INVENTORY VALUATION SUMMARY
A24: SKU Code | B24: Product Name | C24: Units in Stock | D24: Unit Cost | E24: Stock Value (USD) | F24: Incoming PO Units
A25: =A6 -> VF-001 | B25: =B6 -> Omega-3 Fish Oil 90 caps | C25: =D6 -> 850 | D25: =C6 -> 8.5 | E25: =C25*D25 -> 7225 | F25: =SUMIF($B$14:$B$20,A25,$D$14:$D$20) -> 2200
A26: =A7 -> VF-002 | B26: =B7 -> Magnesium Complex 60 caps | C26: =D7 -> 520 | D26: =C7 -> 6.8 | E26: =C26*D26 -> 3536 | F26: =SUMIF($B$14:$B$20,A26,$D$14:$D$20) -> 800
A27: =A8 -> VF-003 | B27: =B8 -> Vitamin D3 120 caps | C27: =D8 -> 430 | D27: =C8 -> 5.9 | E27: =C27*D27 -> 2537 | F27: =SUMIF($B$14:$B$20,A27,$D$14:$D$20) -> 1600
A28: =A9 -> VF-004 | B28: =B9 -> Collagen Peptides 500g | C28: =D9 -> 310 | D28: =C9 -> 12.4 | E28: =C28*D28 -> 3844 | F28: =SUMIF($B$14:$B$20,A28,$D$14:$D$20) -> 600
A29: =A10 -> VF-005 | B29: =B10 -> Probiotic Blend 30 caps | C29: =D10 -> 680 | D29: =C10 -> 9.2 | E29: =C29*D29 -> 6256 | F29: =SUMIF($B$14:$B$20,A29,$D$14:$D$20) -> 1000
A30: TOTAL | E30: =SUM(E25:E29) -> 23398 | F30: =SUM(F25:F29) -> 6200

Sheet DEMAND FORECAST
A1: VITAFLOW HEALTH — DEMAND FORECAST (JAN–JUN 2025)
A2: Projected sales demand by SKU using historical averages, growth rates and seasonality from ASSUMPTIONS tab.
A4: ACTIVE SCENARIO CONTROLS
A5: Active Scenario: | B5: Best | C5: Growth Rate Applied: | D5: (formula below) | E5: =IF(B5="Best",ASSUMPTIONS!$B$13, IF(B5="Conservative",ASSUMPTIONS!$B$14,ASSUMPTIONS!$B$12)) -> 0.1
A7: SKU-LEVEL MONTHLY DEMAND FORECAST (UNITS
A8: SKU Code | B8: Product Name | C8: 45658 | D8: 45689 | E8: 45717 | F8: 45748 | G8: 45778 | H8: 45809 | I8: Total Units | J8: Total Revenue
A9: =ASSUMPTIONS!A34 -> VF-001 | B9: =ASSUMPTIONS!B34 -> Omega-3 Fish Oil 90 caps | C9: =ROUND('SALES DATA'!N5*(1+'DEMAND FORECAST'!$E$5)*'DEMAND FORECAST'!$B$18,0) -> 604 | D9: =ROUND(C9*(1+$E$5)*$B$19,0) -> 598 | E9: =ROUND(D9*(1+$E$5)*$B$20,0) -> 592 | F9: =ROUND(E9*(1+$E$5)*B21,0) -> 651 | G9: =ROUND(F9*(1+$E$5)*B22,0) -> 716 | H9: =ROUND(G9*(1+$E$5)*B23,0) -> 788 | I9: =SUM(C9:H9) -> 3949 | J9: =I9*VLOOKUP(A9,ASSUMPTIONS!$A$34:$C$38,3,0) -> 98685.51
A10: =ASSUMPTIONS!A35 -> VF-002 | B10: =ASSUMPTIONS!B35 -> Magnesium Complex 60 caps | C10: =ROUND('SALES DATA'!N6*(1+'DEMAND FORECAST'!$E$5)*'DEMAND FORECAST'!$B$18,0) -> 446 | D10: =ROUND(C10*(1+$E$5)*$B$19,0) -> 442 | E10: =ROUND(D10*(1+$E$5)*$B$20,0) -> 438 | F10: =ROUND(E10*(1+$E$5)*B21,0) -> 482 | G10: =ROUND(F10*(1+$E$5)*B22,0) -> 530 | H10: =ROUND(G10*(1+$E$5)*B23,0) -> 583 | I10: =SUM(C10:H10) -> 2921 | J10: =I10*VLOOKUP(A10,ASSUMPTIONS!$A$34:$C$38,3,0) -> 58390.79
A11: =ASSUMPTIONS!A36 -> VF-003 | B11: =ASSUMPTIONS!B36 -> Vitamin D3 120 caps | C11: =ROUND('SALES DATA'!N7*(1+'DEMAND FORECAST'!$E$5)*'DEMAND FORECAST'!$B$18,0) -> 396 | D11: =ROUND(C11*(1+$E$5)*$B$19,0) -> 392 | E11: =ROUND(D11*(1+$E$5)*$B$20,0) -> 388 | F11: =ROUND(E11*(1+$E$5)*B21,0) -> 427 | G11: =ROUND(F11*(1+$E$5)*B22,0) -> 470 | H11: =ROUND(G11*(1+$E$5)*B23,0) -> 517 | I11: =SUM(C11:H11) -> 2590 | J11: =I11*VLOOKUP(A11,ASSUMPTIONS!$A$34:$C$38,3,0) -> 46594.1
A12: =ASSUMPTIONS!A37 -> VF-004 | B12: =ASSUMPTIONS!B37 -> Collagen Peptides 500g | C12: =ROUND('SALES DATA'!N8*(1+'DEMAND FORECAST'!$E$5)*'DEMAND FORECAST'!$B$18,0) -> 317 | D12: =ROUND(C12*(1+$E$5)*$B$19,0) -> 314 | E12: =ROUND(D12*(1+$E$5)*$B$20,0) -> 311 | F12: =ROUND(E12*(1+$E$5)*B21,0) -> 342 | G12: =ROUND(F12*(1+$E$5)*B22,0) -> 376 | H12: =ROUND(G12*(1+$E$5)*B23,0) -> 414 | I12: =SUM(C12:H12) -> 2074 | J12: =I12*VLOOKUP(A12,ASSUMPTIONS!$A$34:$C$38,3,0) -> 72569.26
A13: =ASSUMPTIONS!A38 -> VF-005 | B13: =ASSUMPTIONS!B38 -> Probiotic Blend 30 caps | C13: =ROUND('SALES DATA'!N9*(1+'DEMAND FORECAST'!$E$5)*'DEMAND FORECAST'!$B$18,0) -> 505 | D13: =ROUND(C13*(1+$E$5)*$B$19,0) -> 500 | E13: =ROUND(D13*(1+$E$5)*$B$20,0) -> 495 | F13: =ROUND(E13*(1+$E$5)*B21,0) -> 545 | G13: =ROUND(F13*(1+$E$5)*B22,0) -> 600 | H13: =ROUND(G13*(1+$E$5)*B23,0) -> 660 | I13: =SUM(C13:H13) -> 3305 | J13: =I13*VLOOKUP(A13,ASSUMPTIONS!$A$34:$C$38,3,0) -> 99116.95
A14: MONTHLY TOTAL | C14: =SUM(C9:C13) -> 2268 | D14: =SUM(D9:D13) -> 2246 | E14: =SUM(E9:E13) -> 2224 | F14: =SUM(F9:F13) -> 2447 | G14: =SUM(G9:G13) -> 2692 | H14: =SUM(H9:H13) -> 2962 | I14: =SUM(I9:I13) -> 14839 | J14: =SUM(J9:J13) -> 375356.61
A15: TOTAL FORECAST REVENUE (USD) | C15: {=SUMPRODUCT(C$9:C$13,VLOOKUP($A$9:$A$13,ASSUMPTIONS!$A$34:$C$38,3,0))} -> 57370.32 | D15: {=SUMPRODUCT(D$9:D$13,VLOOKUP($A$9:$A$13,ASSUMPTIONS!$A$34:$C$38,3,0))} -> 56813.54 | E15: {=SUMPRODUCT(E$9:E$13,VLOOKUP($A$9:$A$13,ASSUMPTIONS!$A$34:$C$38,3,0))} -> 56256.76 | F15: {=SUMPRODUCT(F$9:F$13,VLOOKUP($A$9:$A$13,ASSUMPTIONS!$A$34:$C$38,3,0))} -> 61896.53 | G15: {=SUMPRODUCT(G$9:G$13,VLOOKUP($A$9:$A$13,ASSUMPTIONS!$A$34:$C$38,3,0))} -> 68093.08 | H15: {=SUMPRODUCT(H$9:H$13,VLOOKUP($A$9:$A$13,ASSUMPTIONS!$A$34:$C$38,3,0))} -> 74926.38 | I15: {=SUMPRODUCT(I$9:I$13,VLOOKUP($A$9:$A$13,ASSUMPTIONS!$A$34:$C$38,3,0))} -> 375356.61
A16: SEASONALITY HELPER
A17: Month | B17: Season Adjustment
A18: Jan | B18: =1+ASSUMPTIONS!$B$17 -> 0.9
A19: Feb | B19: =1+ASSUMPTIONS!$B$17 -> 0.9
A20: Mar | B20: =1+ASSUMPTIONS!$B$17 -> 0.9
A21: Apr | B21: 1
A22: May | B22: 1
A23: Jun | B23: 1
A25: STOCKOUT RISK ANALYSIS
A26: SKU Code | B26: Product Name | C26: Current Stock | D26: Forecast Demand (6 Months) | E26: Incoming PO Units | F26: Projected Closing Stock | G26: Stockout Risk? | I26: Action Required
A27: =A9 -> VF-001 | B27: =B9 -> Omega-3 Fish Oil 90 caps | C27: =INVENTORY!D6 -> 850 | D27: =I9 -> 3949 | E27: =INVENTORY!F25 -> 2200 | F27: =C27-D27+E27 -> -899 | G27: =IF(F27<0,"🔴 STOCKOUT RISK",IF(F27<INVENTORY!H6,"🟡 LOW STOCK","🟢 SUFFICIENT")) -> 🔴 STOCKOUT RISK | I27: =IF(F27<0,"Raise PO immediately",IF(F27<INVENTORY!H6,"Monitor closely","No action needed")) -> Raise PO immediately
A28: =A10 -> VF-002 | B28: =B10 -> Magnesium Complex 60 caps | C28: =INVENTORY!D7 -> 520 | D28: =I10 -> 2921 | E28: =INVENTORY!F26 -> 800 | F28: =C28-D28+E28 -> -1601 | G28: =IF(F28<0,"🔴 STOCKOUT RISK",IF(F28<INVENTORY!H7,"🟡 LOW STOCK","🟢 SUFFICIENT")) -> 🔴 STOCKOUT RISK | I28: =IF(F28<0,"Raise PO immediately",IF(F28<INVENTORY!H7,"Monitor closely","No action needed")) -> Raise PO immediately
A29: =A11 -> VF-003 | B29: =B11 -> Vitamin D3 120 caps | C29: =INVENTORY!D8 -> 430 | D29: =I11 -> 2590 | E29: =INVENTORY!F27 -> 1600 | F29: =C29-D29+E29 -> -560 | G29: =IF(F29<0,"🔴 STOCKOUT RISK",IF(F29<INVENTORY!H8,"🟡 LOW STOCK","🟢 SUFFICIENT")) -> 🔴 STOCKOUT RISK | I29: =IF(F29<0,"Raise PO immediately",IF(F29<INVENTORY!H8,"Monitor closely","No action needed")) -> Raise PO immediately
A30: =A12 -> VF-004 | B30: =B12 -> Collagen Peptides 500g | C30: =INVENTORY!D9 -> 310 | D30: =I12 -> 2074 | E30: =INVENTORY!F28 -> 600 | F30: =C30-D30+E30 -> -1164 | G30: =IF(F30<0,"🔴 STOCKOUT RISK",IF(F30<INVENTORY!H9,"🟡 LOW STOCK","🟢 SUFFICIENT")) -> 🔴 STOCKOUT RISK | I30: =IF(F30<0,"Raise PO immediately",IF(F30<INVENTORY!H9,"Monitor closely","No action needed")) -> Raise PO immediately
A31: =A13 -> VF-005 | B31: =B13 -> Probiotic Blend 30 caps | C31: =INVENTORY!D10 -> 680 | D31: =I13 -> 3305 | E31: =INVENTORY!F29 -> 1000 | F31: =C31-D31+E31 -> -1625 | G31: =IF(F31<0,"🔴 STOCKOUT RISK",IF(F31<INVENTORY!H10,"🟡 LOW STOCK","🟢 SUFFICIENT")) -> 🔴 STOCKOUT RISK | I31: =IF(F31<0,"Raise PO immediately",IF(F31<INVENTORY!H10,"Monitor closely","No action needed")) -> Raise PO immediately

Sheet CASH FLOW
A1: VITAFLOW HEALTH — CASH FLOW FORECAST (JAN–JUN 2025)
A2: Monthly cash inflows and outflows. All values in USD. Linked to ASSUMPTIONS, INVENTORY and DEMAND FORECAST tabs
A4: CASH FLOW ITEMS | B4: 45658 | C4: 45689 | D4: 45717 | E4: 45748 | F4: 45778 | G4: 45809 | H4: TOTAL
A5: OPENING CASH BALANCE | B5: =ASSUMPTIONS!B28 -> 50000 | C5: =B21 -> 63418.341 | D5: =C21 -> 67494.008 | E5: =D21 -> 74625.002 | F5: =E21 -> 98006.073 | G5: =F21 -> 118969.89 | H5: =G21 -> 144050.25
A7: CASH INFLOWS
A8: Shopify Sales Revenue (payout adjusted) | B8: ='DEMAND FORECAST'!C$15*(1-ASSUMPTIONS!$B$31) -> 55706.581 | C8: ='DEMAND FORECAST'!D$15*(1-ASSUMPTIONS!$B$31) -> 55165.947 | D8: ='DEMAND FORECAST'!E$15*(1-ASSUMPTIONS!$B$31) -> 54625.314 | E8: ='DEMAND FORECAST'!F$15*(1-ASSUMPTIONS!$B$31) -> 60101.531 | F8: ='DEMAND FORECAST'!G$15*(1-ASSUMPTIONS!$B$31) -> 66118.381 | G8: ='DEMAND FORECAST'!H$15*(1-ASSUMPTIONS!$B$31) -> 72753.515 | H8: =SUM(B8:G8) -> 364471.27
A9: Other Income (refunds recovered, misc) | B9: 320 | C9: 290 | D9: 310 | E9: 350 | F9: 330 | G9: 360 | H9: =SUM(B9:G9) -> 1960
A10: TOTAL CASH INFLOWS | B10: =SUM(B8:B9) -> 56026.581 | C10: =SUM(C8:C9) -> 55455.947 | D10: =SUM(D8:D9) -> 54935.314 | E10: =SUM(E8:E9) -> 60451.531 | F10: =SUM(F8:F9) -> 66448.381 | G10: =SUM(G8:G9) -> 73113.515 | H10: =SUM(H8:H9) -> 366431.27
A12: CASH OUTFLOWS
A13: Inventory / Supplier Payments (PO settlements) | B13: 10200 | C13: 18976 | D13: 14904 | E13: 4130 | F13: 12000 | G13: 14500 | H13: =SUM(B13:G13) -> 74710
A14: Monthly Operating Expenses | B14: =ASSUMPTIONS!$B$29 -> 28000 | C14: =ASSUMPTIONS!$B$29 -> 28000 | D14: =ASSUMPTIONS!$B$29 -> 28000 | E14: =ASSUMPTIONS!$B$29 -> 28000 | F14: =ASSUMPTIONS!$B$29 -> 28000 | G14: =ASSUMPTIONS!$B$29 -> 28000 | H14: =SUM(B14:G14) -> 168000
A15: Shipping & Fulfilment Costs | B15: =ROUND(('DEMAND FORECAST'!C14/25)*ASSUMPTIONS!$B$30,2) -> 408.24 | C15: =ROUND(('DEMAND FORECAST'!D14/25)*ASSUMPTIONS!$B$30,2) -> 404.28 | D15: =ROUND(('DEMAND FORECAST'!E14/25)*ASSUMPTIONS!$B$30,2) -> 400.32 | E15: =ROUND(('DEMAND FORECAST'!F14/25)*ASSUMPTIONS!$B$30,2) -> 440.46 | F15: =ROUND(('DEMAND FORECAST'!G14/25)*ASSUMPTIONS!$B$30,2) -> 484.56 | G15: =ROUND(('DEMAND FORECAST'!H14/25)*ASSUMPTIONS!$B$30,2) -> 533.16 | H15: =SUM(B15:G15) -> 2671.02
A16: Marketing & Advertising | B16: 3500 | C16: 3500 | D16: 4000 | E16: 4000 | F16: 4500 | G16: 4500 | H16: =SUM(B16:G16) -> 24000
A17: Platform & Software Fees (Shopify, tools) | B17: 500 | C17: 500 | D17: 500 | E17: 500 | F17: 500 | G17: 500 | H17: =SUM(B17:G17) -> 3000
A18: TOTAL CASH OUTFLOWS | B18: =SUM(B13:B17) -> 42608.24 | C18: =SUM(C13:C17) -> 51380.28 | D18: =SUM(D13:D17) -> 47804.32 | E18: =SUM(E13:E17) -> 37070.46 | F18: =SUM(F13:F17) -> 45484.56 | G18: =SUM(G13:G17) -> 48033.16 | H18: =SUM(H13:H17) -> 272381.02
A20: NET CASH FLOW (Inflows minus Outflows) | B20: =B10-B18 -> 13418.341 | C20: =C10-C18 -> 4075.6673 | D20: =D10-D18 -> 7130.994 | E20: =E10-E18 -> 23381.071 | F20: =F10-F18 -> 20963.821 | G20: =G10-G18 -> 25080.355 | H20: =H10-H18 -> 94050.248
A21: CLOSING CASH BALANCE | B21: =B5+B20 -> 63418.341 | C21: =C5+C20 -> 67494.008 | D21: =D5+D20 -> 74625.002 | E21: =E5+E20 -> 98006.073 | F21: =F5+F20 -> 118969.89 | G21: =G5+G20 -> 144050.25 | H21: =G21 -> 144050.25
A23: CASH CONSTRAINT ALERTS
A24: Month | B24: Closing Balance | C24: Min Safe Balance | D24: Variance | E24: Alert
A25: 45658 | B25: =B21 -> 63418.341 | C25: =ASSUMPTIONS!$B$29 -> 28000 | D25: =B25-C25 -> 35418.341 | E25: =IF(B25<0,"🔴 CASH NEGATIVE",IF(B25<C25,"🟡 BELOW SAFE LEVEL","🟢 HEALTHY")) -> 🟢 HEALTHY
A26: 45689 | B26: =C21 -> 67494.008 | C26: =ASSUMPTIONS!$B$29 -> 28000 | D26: =B26-C26 -> 39494.008 | E26: =IF(B26<0,"🔴 CASH NEGATIVE",IF(B26<C26,"🟡 BELOW SAFE LEVEL","🟢 HEALTHY")) -> 🟢 HEALTHY
A27: 45717 | B27: =D21 -> 74625.002 | C27: =ASSUMPTIONS!$B$29 -> 28000 | D27: =B27-C27 -> 46625.002 | E27: =IF(B27<0,"🔴 CASH NEGATIVE",IF(B27<C27,"🟡 BELOW SAFE LEVEL","🟢 HEALTHY")) -> 🟢 HEALTHY
A28: 45748 | B28: =E21 -> 98006.073 | C28: =ASSUMPTIONS!$B$29 -> 28000 | D28: =B28-C28 -> 70006.073 | E28: =IF(B28<0,"🔴 CASH NEGATIVE",IF(B28<C28,"🟡 BELOW SAFE LEVEL","🟢 HEALTHY")) -> 🟢 HEALTHY
A29: 45778 | B29: =F21 -> 118969.89 | C29: =ASSUMPTIONS!$B$29 -> 28000 | D29: =B29-C29 -> 90969.893 | E29: =IF(B29<0,"🔴 CASH NEGATIVE",IF(B29<C29,"🟡 BELOW SAFE LEVEL","🟢 HEALTHY")) -> 🟢 HEALTHY
A30: 45809 | B30: =G21 -> 144050.25 | C30: =ASSUMPTIONS!$B$29 -> 28000 | D30: =B30-C30 -> 116050.25 | E30: =IF(B30<0,"🔴 CASH NEGATIVE",IF(B30<C30,"🟡 BELOW SAFE LEVEL","🟢 HEALTHY")) -> 🟢 HEALTHY

Sheet SCENARIOS
A1: VITAFLOW HEALTH — SCENARIO ANALYSIS MODEL
A2: Compare Best, Base and Conservative scenarios side by side. Change ASSUMPTIONS!B15 to switch active scenario across all tabs
A4: SCENARIO ASSUMPTION INPUTS
A5: Assumption | B5: Conservative | C5: Base | D5: Best | E5: Active (Live)
A6: Monthly Revenue Growth Rate | B6: 0.02 | C6: 0.05 | D6: 0.1 | E6: =ASSUMPTIONS!B12 -> 0.05
A7: Q4 Seasonality Boost | B7: 0.15 | C7: 0.2 | D7: 0.3 | E7: =ASSUMPTIONS!B16 -> 0.2
A8: Q1 Seasonality Impact | B8: -0.15 | C8: -0.1 | D8: -0.05 | E8: =ASSUMPTIONS!B17 -> -0.1
A9: Opening Cash Balance | B9: 50000 | C9: 50000 | D9: 50000 | E9: =ASSUMPTIONS!B28 -> 50000
A10: Monthly Operating Expenses | B10: 29000 | C10: 28000 | D10: 27500 | E10: =ASSUMPTIONS!B29 -> 28000
A11: Supplier Payment Terms (Days) | B11: 45 | C11: 30 | D11: 21 | E11: =ASSUMPTIONS!B27 -> 30
A12: Inventory Lead Time (Days) | B12: 45 | C12: 35 | D12: 25 | E12: =ASSUMPTIONS!B21 -> 40
A14: SCENARIO SWITCHER
A15: Currently Active Scenario: | B15: =ASSUMPTIONS!B15 -> Base | C15: To switch: go to ASSUMPTIONS tab → change cell B15
A16: Scenario Status: | B16: =IF(ASSUMPTIONS!$B$15="Best","🟢 BEST CASE ACTIVE",IF(ASSUMPTIONS!$B$15="Conservative","🔴 CONSERVATIVE CASE ACTIVE","🟡 BASE CASE ACTIVE")) -> 🟡 BASE CASE ACTIVE
A18: REVENUE FORECAST — ALL SCENARIOS (USD)
A19: Month | B19: Conservative | C19: Base | D19: Best | E19: Active Scenario
A20: 45658 | B20: =ROUND(('SALES DATA'!O19/12)*(1+$B$6)*(1+$B$8),2) -> 30533.11 | C20: =ROUND(('SALES DATA'!O19/12)*(1+$C$6)*(1+$C$8),2) -> 33280.03 | D20: =ROUND(('SALES DATA'!O19/12)*(1+$D$6)*(1+$D$8),2) -> 36801.73 | E20: =IF(ASSUMPTIONS!$B$15="Conservative",B20,IF(ASSUMPTIONS!$B$15="Best",D20,C20)) -> 33280.03
A21: 45689 | B21: =ROUND(B20*(1+$B$6),2) -> 31143.77 | C21: =ROUND(C20*(1+$C$6),2) -> 34944.03 | D21: =ROUND(D20*(1+$D$6),2) -> 40481.9 | E21: =IF(ASSUMPTIONS!$B$15="Conservative",B21,IF(ASSUMPTIONS!$B$15="Best",D21,C21)) -> 34944.03
A22: 45717 | B22: =ROUND(B21*(1+$B$6),2) -> 31766.65 | C22: =ROUND(C21*(1+$C$6),2) -> 36691.23 | D22: =ROUND(D21*(1+$D$6),2) -> 44530.09 | E22: =IF(ASSUMPTIONS!$B$15="Conservative",B22,IF(ASSUMPTIONS!$B$15="Best",D22,C22)) -> 36691.23
A23: 45748 | B23: =ROUND(B22*(1+$B$6),2) -> 32401.98 | C23: =ROUND(C22*(1+$C$6),2) -> 38525.79 | D23: =ROUND(D22*(1+$D$6),2) -> 48983.1 | E23: =IF(ASSUMPTIONS!$B$15="Conservative",B23,IF(ASSUMPTIONS!$B$15="Best",D23,C23)) -> 38525.79
A24: 45778 | B24: =ROUND(B23*(1+$B$6),2) -> 33050.02 | C24: =ROUND(C23*(1+$C$6),2) -> 40452.08 | D24: =ROUND(D23*(1+$D$6),2) -> 53881.41 | E24: =IF(ASSUMPTIONS!$B$15="Conservative",B24,IF(ASSUMPTIONS!$B$15="Best",D24,C24)) -> 40452.08
A25: 45809 | B25: =ROUND(B24*(1+$B$6),2) -> 33711.02 | C25: =ROUND(C24*(1+$C$6),2) -> 42474.68 | D25: =ROUND(D24*(1+$D$6),2) -> 59269.55 | E25: =IF(ASSUMPTIONS!$B$15="Conservative",B25,IF(ASSUMPTIONS!$B$15="Best",D25,C25)) -> 42474.68
A26: 6-MONTH TOTAL | B26: =SUM(B20:B25) -> 192606.55 | C26: =SUM(C20:C25) -> 226367.84 | D26: =SUM(D20:D25) -> 283947.78 | E26: =SUM(E20:E25) -> 226367.84
A28: CLOSING CASH BALANCE — ALL SCENARIOS
A29: Month | B29: Conservative | C29: Base | D29: Best | E29: Variance (Best vs Conservative)
A30: 45658 | B30: =ASSUMPTIONS!$B$28+B20-$B$10-INVENTORY!$F$21/6 -> 43163.11 | C30: =ASSUMPTIONS!$B$28+C20-$D$10-INVENTORY!$F$21/6 -> 47410.03 | D30: =ASSUMPTIONS!$B$28+D20-$D$10-INVENTORY!$F$21/6 -> 50931.73 | E30: =D30-B30 -> 7768.62
A31: 45689 | B31: =B30+B21-B$10-INVENTORY!$F$21/6 -> 36936.88 | C31: =C30+C21-C$10-INVENTORY!$F$21/6 -> 45984.06 | D31: =D30+D21-D$10-INVENTORY!$F$21/6 -> 55543.63 | E31: =E30+E21-E$10-INVENTORY!$F$21/6 -> 6342.65
A32: 45717 | B32: =B31+B22-B$10-INVENTORY!$F$21/6 -> 31333.53 | C32: =C31+C22-C$10-INVENTORY!$F$21/6 -> 46305.29 | D32: =D31+D22-D$10-INVENTORY!$F$21/6 -> 64203.72 | E32: =E31+E22-E$10-INVENTORY!$F$21/6 -> 6663.88
A33: 45748 | B33: =B32+B23-B$10-INVENTORY!$F$21/6 -> 26365.51 | C33: =C32+C23-C$10-INVENTORY!$F$21/6 -> 48461.08 | D33: =D32+D23-D$10-INVENTORY!$F$21/6 -> 77316.82 | E33: =E32+E23-E$10-INVENTORY!$F$21/6 -> 8819.67
A34: 45778 | B34: =B33+B24-B$10-INVENTORY!$F$21/6 -> 22045.53 | C34: =C33+C24-C$10-INVENTORY!$F$21/6 -> 52543.16 | D34: =D33+D24-D$10-INVENTORY!$F$21/6 -> 95328.23 | E34: =E33+E24-E$10-INVENTORY!$F$21/6 -> 12901.75
A35: 45809 | B35: =B34+B25-B$10-INVENTORY!$F$21/6 -> 18386.55 | C35: =C34+C25-C$10-INVENTORY!$F$21/6 -> 58647.84 | D35: =D34+D25-D$10-INVENTORY!$F$21/6 -> 118727.78 | E35: =E34+E25-E$10-INVENTORY!$F$21/6 -> 19006.43
A36: BEST vs CONSERVATIVE GAP | E36: =E35 -> 19006.43
A38: SCENARIO SUMMARY CARD
A39: Metric | B39: Conservative | C39: Base | D39: Best
A40: 6-Month Revenue | B40: =B26 -> 192606.55 | C40: =C26 -> 226367.84 | D40: =D26 -> 283947.78
A41: Jun Closing Cash | B41: =B35 -> 18386.55 | C41: =C35 -> 58647.84 | D41: =D35 -> 118727.78
A42: Growth Rate Applied | B42: =B6 -> 0.02 | C42: =C6 -> 0.05 | D42: =D6 -> 0.1
A43: Opex Assumption | B43: =B10 -> 29000 | C43: =C10 -> 28000 | D43: =D10 -> 27500

Sheet DASHBOARD
B2: VITAFLOW HEALTH — FINANCIAL & INVENTORY INTELLIGENCE DASHBOARD
B3: Forecast Period: Jan–Jun 2025 | Base Currency: USD | Scenario: | L3: =ASSUMPTIONS!B15 -> Base
L4: Last Updated: | M4: =TODAY() -> 46121
B5: 6-MONTH REVENUE | E5: CLOSING CASH (JUN) | H5: TOTAL UNITS FORECAST | K5: OPEN PO VALUE
B6: =SUM('DEMAND FORECAST'!C15:H15) -> 375356.61 | E6: ='CASH FLOW'!G21 -> 144050.25 | H6: =SUM('DEMAND FORECAST'!I9:I13) -> 14839 | K6: =INVENTORY!F21 -> 50220
B7: Jan–Jun 2025 (Active Scenario) | E7: End of Forecast Period | H7: Across All 5 SKUs | K7: Across 7 Open POs
B9: STOCKOUT ALERTS
B10: =COUNTIF('DEMAND FORECAST'!G27:G31,"🔴 STOCKOUT RISK") -> 5
B11: SKUs at Risk
B30: SKU PERFORMANCE SUMMARY
B31: SKU | C31: Product | D31: 2024 Total Units | E31: 2024 Revenue | F31: Forecast Units (6M) | G31: Forecast Revenue | H31: Current Stock | I31: Days of Stock | J31: Stock Status | K31: Avg Unit Price | L31: Unit Cost | M31: Gross Margin %
B32: {=INVENTORY!A6:A10} -> VF-001 | C32: {=_xlfn.ANCHORARRAY(INVENTORY!B6)} -> Omega-3 Fish Oil 90 caps | D32: {='SALES DATA'!O5:O9} -> 4640 | E32: {='SALES DATA'!O14:O18} -> 115953.6 | F32: {='DEMAND FORECAST'!I9:I13} -> 3949 | G32: {='DEMAND FORECAST'!J9:J13} -> 98685.51 | H32: {=INVENTORY!D6:D10} -> 850 | I32: {=INVENTORY!F6:F10} -> 66.864224 | J32: {=INVENTORY!I6:I10} -> 🟢 OK | K32: =VLOOKUP(B32,ASSUMPTIONS!$A$34:$C$38,3,0) -> 24.99 | L32: {=INVENTORY!C6:C10} -> 8.5 | M32: =IFERROR((K32-L32)/K32,0) -> 0.65986395
B33: VF-002 | C33: Magnesium Complex 60 caps | D33: 3250 | E33: 64967.5 | F33: 2921 | G33: 58390.79 | H33: 520 | I33: 58.4 | J33: 🟢 OK | K33: =VLOOKUP(B33,ASSUMPTIONS!$A$34:$C$38,3,0) -> 19.99 | L33: 6.8 | M33: =IFERROR((K33-L33)/K33,0) -> 0.65982991
B34: VF-003 | C34: Vitamin D3 120 caps | D34: 2675 | E34: 48123.25 | F34: 2590 | G34: 46594.1 | H34: 430 | I34: 58.672897 | J34: 🟢 OK | K34: =VLOOKUP(B34,ASSUMPTIONS!$A$34:$C$38,3,0) -> 17.99 | L34: 5.9 | M34: =IFERROR((K34-L34)/K34,0) -> 0.67204002
B35: VF-004 | C35: Collagen Peptides 500g | D35: 2262 | E35: 79147.38 | F35: 2074 | G35: 72569.26 | H35: 310 | I35: 50.022104 | J35: 🟡 REORDER NOW | K35: =VLOOKUP(B35,ASSUMPTIONS!$A$34:$C$38,3,0) -> 34.99 | L35: 12.4 | M35: =IFERROR((K35-L35)/K35,0) -> 0.64561303
B36: VF-005 | C36: Probiotic Blend 30 caps | D36: 3815 | E36: 114411.85 | F36: 3305 | G36: 99116.95 | H36: 680 | I36: 65.058978 | J36: 🟢 OK | K36: =VLOOKUP(B36,ASSUMPTIONS!$A$34:$C$38,3,0) -> 29.99 | L36: 9.2 | M36: =IFERROR((K36-L36)/K36,0) -> 0.69323108
B37: TOTAL | D37: =SUM(D32:D36) -> 16642 | E37: =SUM(E32:E36) -> 422603.58 | F37: =SUM(F32:F36) -> 14839 | G37: =SUM(G32:G36) -> 375356.61
B39: CASH FLOW SUMMARY | G39: ACTIVE ASSUMPTIONS SNAPSHOT
B40: Month | C40: Inflows | D40: Outflows | E40: Net Flow | G40: Growth Rate | H40: =ASSUMPTIONS!B12 -> 0.05
B41: 228279 | C41: ='CASH FLOW'!$B$10 -> 56026.581 | D41: ='CASH FLOW'!$B$18 -> 42608.24 | E41: ='CASH FLOW'!$B$20 -> 13418.341 | G41: Active Scenario | H41: =ASSUMPTIONS!B15 -> Base
B42: 228310 | C42: ='CASH FLOW'!$C$10 -> 55455.947 | D42: ='CASH FLOW'!$C$18 -> 51380.28 | E42: ='CASH FLOW'!$C$20 -> 4075.6673 | G42: Opening Cash | H42: =ASSUMPTIONS!B28 -> 50000
B43: 228338 | C43: ='CASH FLOW'!$D$10 -> 54935.314 | D43: ='CASH FLOW'!$D$18 -> 47804.32 | E43: ='CASH FLOW'!$D$20 -> 7130.994 | G43: Monthly Opex | H43: =ASSUMPTIONS!B29 -> 28000
B44: 228369 | C44: ='CASH FLOW'!$E$10 -> 60451.531 | D44: ='CASH FLOW'!$E$18 -> 37070.46 | E44: ='CASH FLOW'!$E$20 -> 23381.071
B45: 228399 | C45: ='CASH FLOW'!$F$10 -> 66448.381 | D45: ='CASH FLOW'!$F$18 -> 45484.56 | E45: ='CASH FLOW'!$F$20 -> 20963.821
B46: 228430 | C46: ='CASH FLOW'!$G$10 -> 73113.515 | D46: ='CASH FLOW'!$G$18 -> 48033.16 | E46: ='CASH FLOW'!$G$20 -> 25080.355
B47: Totals | C47: =SUM(C41:C46) -> 366431.27 | D47: =SUM(D41:D46) -> 272381.02 | E47: =SUM(E41:E46) -> 94050.248
B56: CHART DATA — DO NOT EDIT
B57: Month | C57: Conservative | D57: Base | E57: Best
B58: 45658 | C58: {=SCENARIOS!B20:D25} -> 30533.11 | D58: 33280.03 | E58: 36801.73
B59: 45689 | C59: 31143.77 | D59: 34944.03 | E59: 40481.9
B60: 45717 | C60: 31766.65 | D60: 36691.23 | E60: 44530.09
B61: 45748 | C61: 32401.98 | D61: 38525.79 | E61: 48983.1
B62: 45778 | C62: 33050.02 | D62: 40452.08 | E62: 53881.41
B63: 45809 | C63: 33711.02 | D63: 42474.68 | E63: 59269.55
B65: Month | C65: Conservative Cash | D65: Base Cash | E65: Best Cash
B66: 45658 | C66: {=SCENARIOS!B30:D35} -> 43163.11 | D66: 47410.03 | E66: 50931.73
B67: 45689 | C67: 36936.88 | D67: 45984.06 | E67: 55543.63
B68: 45717 | C68: 31333.53 | D68: 46305.29 | E68: 64203.72
B69: 45748 | C69: 26365.51 | D69: 48461.08 | E69: 77316.82
B70: 45778 | C70: 22045.53 | D70: 52543.16 | E70: 95328.23
...
